<?xml version="1.0"?>
<robot name="simple_dynamixel_robot">

    <link name="parent_link">
        <!-- empty link -->
    </link>

    <link name="child_link">
        <!-- empty link -->
    </link>

    <joint name="trinamic_joint" type="revolute">

        <!-- Limits -->
        <limit lower="-1.0" upper="1.0" velocity="5.0" effort="10.0"/>

        <!-- Soft Limits -->
        <safety_controller k_position="10" k_velocity="10"  soft_lower_limit="-0.9" soft_upper_limit="0.9" />

        <parent link="parent_link"/>
        <child link="child_link"/>
        <axis xyz="0 0 1"/>
        <origin xyz="0 0 0" rpy="0.0 0.0 0.0"/>
    </joint>

</robot>
